[2022-10-10 07:35:09,750] {taskinstance.py:1032} INFO - Dependencies all met for <TaskInstance: weekly_batch.local_to_gcs_task manual__2022-10-10T07:34:53.268131+00:00 [queued]>
[2022-10-10 07:35:09,763] {taskinstance.py:1032} INFO - Dependencies all met for <TaskInstance: weekly_batch.local_to_gcs_task manual__2022-10-10T07:34:53.268131+00:00 [queued]>
[2022-10-10 07:35:09,764] {taskinstance.py:1238} INFO - 
--------------------------------------------------------------------------------
[2022-10-10 07:35:09,765] {taskinstance.py:1239} INFO - Starting attempt 1 of 2
[2022-10-10 07:35:09,766] {taskinstance.py:1240} INFO - 
--------------------------------------------------------------------------------
[2022-10-10 07:35:09,995] {taskinstance.py:1259} INFO - Executing <Task(PythonOperator): local_to_gcs_task> on 2022-10-10 07:34:53.268131+00:00
[2022-10-10 07:35:10,021] {standard_task_runner.py:52} INFO - Started process 342 to run task
[2022-10-10 07:35:10,027] {standard_task_runner.py:76} INFO - Running: ['***', 'tasks', 'run', 'weekly_batch', 'local_to_gcs_task', 'manual__2022-10-10T07:34:53.268131+00:00', '--job-id', '16', '--raw', '--subdir', 'DAGS_FOLDER/dataingestion_gcs_dag.py', '--cfg-path', '/tmp/tmp0gyjszhg', '--error-file', '/tmp/tmp5f38l4xo']
[2022-10-10 07:35:10,030] {standard_task_runner.py:77} INFO - Job 16: Subtask local_to_gcs_task
[2022-10-10 07:35:10,152] {logging_mixin.py:109} INFO - Running <TaskInstance: weekly_batch.local_to_gcs_task manual__2022-10-10T07:34:53.268131+00:00 [running]> on host d09dcbdb0e98
[2022-10-10 07:35:10,354] {taskinstance.py:1426} INFO - Exporting the following env vars:
AIRFLOW_CTX_DAG_OWNER=***
AIRFLOW_CTX_DAG_ID=weekly_batch
AIRFLOW_CTX_TASK_ID=local_to_gcs_task
AIRFLOW_CTX_EXECUTION_DATE=2022-10-10T07:34:53.268131+00:00
AIRFLOW_CTX_DAG_RUN_ID=manual__2022-10-10T07:34:53.268131+00:00
[2022-10-10 07:35:10,390] {taskinstance.py:1700} ERROR - Task failed with exception
Traceback (most recent call last):
  File "/home/airflow/.local/lib/python3.7/site-packages/airflow/models/taskinstance.py", line 1329, in _run_raw_task
    self._execute_task_with_callbacks(context)
  File "/home/airflow/.local/lib/python3.7/site-packages/airflow/models/taskinstance.py", line 1455, in _execute_task_with_callbacks
    result = self._execute_task(context, self.task)
  File "/home/airflow/.local/lib/python3.7/site-packages/airflow/models/taskinstance.py", line 1511, in _execute_task
    result = execute_callable(context=context)
  File "/home/airflow/.local/lib/python3.7/site-packages/airflow/operators/python.py", line 174, in execute
    return_value = self.execute_callable()
  File "/home/airflow/.local/lib/python3.7/site-packages/airflow/operators/python.py", line 185, in execute_callable
    return self.python_callable(*self.op_args, **self.op_kwargs)
  File "/opt/airflow/dags/dataingestion_gcs_dag.py", line 39, in upload_to_gcs
    client = storage.Client(project = PROJECT_ID)
  File "/home/airflow/.local/lib/python3.7/site-packages/google/cloud/storage/client.py", line 128, in __init__
    _http=_http,
  File "/home/airflow/.local/lib/python3.7/site-packages/google/cloud/client.py", line 320, in __init__
    self, credentials=credentials, client_options=client_options, _http=_http
  File "/home/airflow/.local/lib/python3.7/site-packages/google/cloud/client.py", line 178, in __init__
    credentials, _ = google.auth.default(scopes=scopes)
  File "/home/airflow/.local/lib/python3.7/site-packages/google/auth/_default.py", line 459, in default
    credentials, project_id = checker()
  File "/home/airflow/.local/lib/python3.7/site-packages/google/auth/_default.py", line 222, in _get_explicit_environ_credentials
    os.environ[environment_vars.CREDENTIALS]
  File "/home/airflow/.local/lib/python3.7/site-packages/google/auth/_default.py", line 108, in load_credentials_from_file
    "File {} was not found.".format(filename)
google.auth.exceptions.DefaultCredentialsError: File /.google/credentials/google_credentials.json was not found.
[2022-10-10 07:35:10,500] {taskinstance.py:1277} INFO - Marking task as UP_FOR_RETRY. dag_id=weekly_batch, task_id=local_to_gcs_task, execution_date=20221010T073453, start_date=20221010T073509, end_date=20221010T073510
[2022-10-10 07:35:10,547] {standard_task_runner.py:92} ERROR - Failed to execute job 16 for task local_to_gcs_task
Traceback (most recent call last):
  File "/home/airflow/.local/lib/python3.7/site-packages/airflow/task/task_runner/standard_task_runner.py", line 85, in _start_by_fork
    args.func(args, dag=self.dag)
  File "/home/airflow/.local/lib/python3.7/site-packages/airflow/cli/cli_parser.py", line 48, in command
    return func(*args, **kwargs)
  File "/home/airflow/.local/lib/python3.7/site-packages/airflow/utils/cli.py", line 92, in wrapper
    return f(*args, **kwargs)
  File "/home/airflow/.local/lib/python3.7/site-packages/airflow/cli/commands/task_command.py", line 298, in task_run
    _run_task_by_selected_method(args, dag, ti)
  File "/home/airflow/.local/lib/python3.7/site-packages/airflow/cli/commands/task_command.py", line 107, in _run_task_by_selected_method
    _run_raw_task(args, ti)
  File "/home/airflow/.local/lib/python3.7/site-packages/airflow/cli/commands/task_command.py", line 184, in _run_raw_task
    error_file=args.error_file,
  File "/home/airflow/.local/lib/python3.7/site-packages/airflow/utils/session.py", line 70, in wrapper
    return func(*args, session=session, **kwargs)
  File "/home/airflow/.local/lib/python3.7/site-packages/airflow/models/taskinstance.py", line 1329, in _run_raw_task
    self._execute_task_with_callbacks(context)
  File "/home/airflow/.local/lib/python3.7/site-packages/airflow/models/taskinstance.py", line 1455, in _execute_task_with_callbacks
    result = self._execute_task(context, self.task)
  File "/home/airflow/.local/lib/python3.7/site-packages/airflow/models/taskinstance.py", line 1511, in _execute_task
    result = execute_callable(context=context)
  File "/home/airflow/.local/lib/python3.7/site-packages/airflow/operators/python.py", line 174, in execute
    return_value = self.execute_callable()
  File "/home/airflow/.local/lib/python3.7/site-packages/airflow/operators/python.py", line 185, in execute_callable
    return self.python_callable(*self.op_args, **self.op_kwargs)
  File "/opt/airflow/dags/dataingestion_gcs_dag.py", line 39, in upload_to_gcs
    client = storage.Client(project = PROJECT_ID)
  File "/home/airflow/.local/lib/python3.7/site-packages/google/cloud/storage/client.py", line 128, in __init__
    _http=_http,
  File "/home/airflow/.local/lib/python3.7/site-packages/google/cloud/client.py", line 320, in __init__
    self, credentials=credentials, client_options=client_options, _http=_http
  File "/home/airflow/.local/lib/python3.7/site-packages/google/cloud/client.py", line 178, in __init__
    credentials, _ = google.auth.default(scopes=scopes)
  File "/home/airflow/.local/lib/python3.7/site-packages/google/auth/_default.py", line 459, in default
    credentials, project_id = checker()
  File "/home/airflow/.local/lib/python3.7/site-packages/google/auth/_default.py", line 222, in _get_explicit_environ_credentials
    os.environ[environment_vars.CREDENTIALS]
  File "/home/airflow/.local/lib/python3.7/site-packages/google/auth/_default.py", line 108, in load_credentials_from_file
    "File {} was not found.".format(filename)
google.auth.exceptions.DefaultCredentialsError: File /.google/credentials/google_credentials.json was not found.
[2022-10-10 07:35:10,573] {local_task_job.py:154} INFO - Task exited with return code 1
[2022-10-10 07:35:10,644] {local_task_job.py:264} INFO - 0 downstream tasks scheduled from follow-on schedule check
