[2022-10-11 05:39:05,334] {taskinstance.py:1032} INFO - Dependencies all met for <TaskInstance: weekly_batch.local_to_gcs_task manual__2022-10-11T05:33:50.832416+00:00 [queued]>
[2022-10-11 05:39:05,347] {taskinstance.py:1032} INFO - Dependencies all met for <TaskInstance: weekly_batch.local_to_gcs_task manual__2022-10-11T05:33:50.832416+00:00 [queued]>
[2022-10-11 05:39:05,347] {taskinstance.py:1238} INFO - 
--------------------------------------------------------------------------------
[2022-10-11 05:39:05,348] {taskinstance.py:1239} INFO - Starting attempt 2 of 2
[2022-10-11 05:39:05,348] {taskinstance.py:1240} INFO - 
--------------------------------------------------------------------------------
[2022-10-11 05:39:05,366] {taskinstance.py:1259} INFO - Executing <Task(PythonOperator): local_to_gcs_task> on 2022-10-11 05:33:50.832416+00:00
[2022-10-11 05:39:05,373] {standard_task_runner.py:52} INFO - Started process 1800 to run task
[2022-10-11 05:39:05,376] {standard_task_runner.py:76} INFO - Running: ['***', 'tasks', 'run', 'weekly_batch', 'local_to_gcs_task', 'manual__2022-10-11T05:33:50.832416+00:00', '--job-id', '73', '--raw', '--subdir', 'DAGS_FOLDER/bank_weekly_ingest_dag.py', '--cfg-path', '/tmp/tmp81i3mo01', '--error-file', '/tmp/tmpm7ao8f52']
[2022-10-11 05:39:05,377] {standard_task_runner.py:77} INFO - Job 73: Subtask local_to_gcs_task
[2022-10-11 05:39:05,425] {logging_mixin.py:109} INFO - Running <TaskInstance: weekly_batch.local_to_gcs_task manual__2022-10-11T05:33:50.832416+00:00 [running]> on host 6caab34727ce
[2022-10-11 05:39:05,480] {taskinstance.py:1426} INFO - Exporting the following env vars:
AIRFLOW_CTX_DAG_OWNER=***
AIRFLOW_CTX_DAG_ID=weekly_batch
AIRFLOW_CTX_TASK_ID=local_to_gcs_task
AIRFLOW_CTX_EXECUTION_DATE=2022-10-11T05:33:50.832416+00:00
AIRFLOW_CTX_DAG_RUN_ID=manual__2022-10-11T05:33:50.832416+00:00
[2022-10-11 05:39:05,482] {taskinstance.py:1700} ERROR - Task failed with exception
Traceback (most recent call last):
  File "/home/airflow/.local/lib/python3.7/site-packages/airflow/models/taskinstance.py", line 1329, in _run_raw_task
    self._execute_task_with_callbacks(context)
  File "/home/airflow/.local/lib/python3.7/site-packages/airflow/models/taskinstance.py", line 1455, in _execute_task_with_callbacks
    result = self._execute_task(context, self.task)
  File "/home/airflow/.local/lib/python3.7/site-packages/airflow/models/taskinstance.py", line 1511, in _execute_task
    result = execute_callable(context=context)
  File "/home/airflow/.local/lib/python3.7/site-packages/airflow/operators/python.py", line 174, in execute
    return_value = self.execute_callable()
  File "/home/airflow/.local/lib/python3.7/site-packages/airflow/operators/python.py", line 185, in execute_callable
    return self.python_callable(*self.op_args, **self.op_kwargs)
  File "/opt/airflow/dags/bank_weekly_ingest_dag.py", line 37, in upload_to_gcs
    client = storage.Client(project ='firm-pentameter-363006')
  File "/home/airflow/.local/lib/python3.7/site-packages/google/cloud/storage/client.py", line 128, in __init__
    _http=_http,
  File "/home/airflow/.local/lib/python3.7/site-packages/google/cloud/client.py", line 320, in __init__
    self, credentials=credentials, client_options=client_options, _http=_http
  File "/home/airflow/.local/lib/python3.7/site-packages/google/cloud/client.py", line 178, in __init__
    credentials, _ = google.auth.default(scopes=scopes)
  File "/home/airflow/.local/lib/python3.7/site-packages/google/auth/_default.py", line 459, in default
    credentials, project_id = checker()
  File "/home/airflow/.local/lib/python3.7/site-packages/google/auth/_default.py", line 222, in _get_explicit_environ_credentials
    os.environ[environment_vars.CREDENTIALS]
  File "/home/airflow/.local/lib/python3.7/site-packages/google/auth/_default.py", line 108, in load_credentials_from_file
    "File {} was not found.".format(filename)
google.auth.exceptions.DefaultCredentialsError: File /.google/credentials/google_credentials.json was not found.
[2022-10-11 05:39:05,501] {taskinstance.py:1277} INFO - Marking task as FAILED. dag_id=weekly_batch, task_id=local_to_gcs_task, execution_date=20221011T053350, start_date=20221011T053905, end_date=20221011T053905
[2022-10-11 05:39:05,519] {standard_task_runner.py:92} ERROR - Failed to execute job 73 for task local_to_gcs_task
Traceback (most recent call last):
  File "/home/airflow/.local/lib/python3.7/site-packages/airflow/task/task_runner/standard_task_runner.py", line 85, in _start_by_fork
    args.func(args, dag=self.dag)
  File "/home/airflow/.local/lib/python3.7/site-packages/airflow/cli/cli_parser.py", line 48, in command
    return func(*args, **kwargs)
  File "/home/airflow/.local/lib/python3.7/site-packages/airflow/utils/cli.py", line 92, in wrapper
    return f(*args, **kwargs)
  File "/home/airflow/.local/lib/python3.7/site-packages/airflow/cli/commands/task_command.py", line 298, in task_run
    _run_task_by_selected_method(args, dag, ti)
  File "/home/airflow/.local/lib/python3.7/site-packages/airflow/cli/commands/task_command.py", line 107, in _run_task_by_selected_method
    _run_raw_task(args, ti)
  File "/home/airflow/.local/lib/python3.7/site-packages/airflow/cli/commands/task_command.py", line 184, in _run_raw_task
    error_file=args.error_file,
  File "/home/airflow/.local/lib/python3.7/site-packages/airflow/utils/session.py", line 70, in wrapper
    return func(*args, session=session, **kwargs)
  File "/home/airflow/.local/lib/python3.7/site-packages/airflow/models/taskinstance.py", line 1329, in _run_raw_task
    self._execute_task_with_callbacks(context)
  File "/home/airflow/.local/lib/python3.7/site-packages/airflow/models/taskinstance.py", line 1455, in _execute_task_with_callbacks
    result = self._execute_task(context, self.task)
  File "/home/airflow/.local/lib/python3.7/site-packages/airflow/models/taskinstance.py", line 1511, in _execute_task
    result = execute_callable(context=context)
  File "/home/airflow/.local/lib/python3.7/site-packages/airflow/operators/python.py", line 174, in execute
    return_value = self.execute_callable()
  File "/home/airflow/.local/lib/python3.7/site-packages/airflow/operators/python.py", line 185, in execute_callable
    return self.python_callable(*self.op_args, **self.op_kwargs)
  File "/opt/airflow/dags/bank_weekly_ingest_dag.py", line 37, in upload_to_gcs
    client = storage.Client(project ='firm-pentameter-363006')
  File "/home/airflow/.local/lib/python3.7/site-packages/google/cloud/storage/client.py", line 128, in __init__
    _http=_http,
  File "/home/airflow/.local/lib/python3.7/site-packages/google/cloud/client.py", line 320, in __init__
    self, credentials=credentials, client_options=client_options, _http=_http
  File "/home/airflow/.local/lib/python3.7/site-packages/google/cloud/client.py", line 178, in __init__
    credentials, _ = google.auth.default(scopes=scopes)
  File "/home/airflow/.local/lib/python3.7/site-packages/google/auth/_default.py", line 459, in default
    credentials, project_id = checker()
  File "/home/airflow/.local/lib/python3.7/site-packages/google/auth/_default.py", line 222, in _get_explicit_environ_credentials
    os.environ[environment_vars.CREDENTIALS]
  File "/home/airflow/.local/lib/python3.7/site-packages/google/auth/_default.py", line 108, in load_credentials_from_file
    "File {} was not found.".format(filename)
google.auth.exceptions.DefaultCredentialsError: File /.google/credentials/google_credentials.json was not found.
[2022-10-11 05:39:05,549] {local_task_job.py:154} INFO - Task exited with return code 1
[2022-10-11 05:39:05,589] {local_task_job.py:264} INFO - 0 downstream tasks scheduled from follow-on schedule check
