[2022-10-11 05:09:24,309] {taskinstance.py:1032} INFO - Dependencies all met for <TaskInstance: weekly_batch.download_dataset_task manual__2022-10-11T05:09:22.800747+00:00 [queued]>
[2022-10-11 05:09:24,321] {taskinstance.py:1032} INFO - Dependencies all met for <TaskInstance: weekly_batch.download_dataset_task manual__2022-10-11T05:09:22.800747+00:00 [queued]>
[2022-10-11 05:09:24,322] {taskinstance.py:1238} INFO - 
--------------------------------------------------------------------------------
[2022-10-11 05:09:24,322] {taskinstance.py:1239} INFO - Starting attempt 1 of 2
[2022-10-11 05:09:24,323] {taskinstance.py:1240} INFO - 
--------------------------------------------------------------------------------
[2022-10-11 05:09:24,339] {taskinstance.py:1259} INFO - Executing <Task(BashOperator): download_dataset_task> on 2022-10-11 05:09:22.800747+00:00
[2022-10-11 05:09:24,345] {standard_task_runner.py:52} INFO - Started process 496 to run task
[2022-10-11 05:09:24,348] {standard_task_runner.py:76} INFO - Running: ['***', 'tasks', 'run', 'weekly_batch', 'download_dataset_task', 'manual__2022-10-11T05:09:22.800747+00:00', '--job-id', '64', '--raw', '--subdir', 'DAGS_FOLDER/bank_weekly_ingest_dag.py', '--cfg-path', '/tmp/tmp01692ygp', '--error-file', '/tmp/tmprmvkx68c']
[2022-10-11 05:09:24,350] {standard_task_runner.py:77} INFO - Job 64: Subtask download_dataset_task
[2022-10-11 05:09:24,408] {logging_mixin.py:109} INFO - Running <TaskInstance: weekly_batch.download_dataset_task manual__2022-10-11T05:09:22.800747+00:00 [running]> on host 6caab34727ce
[2022-10-11 05:09:24,499] {taskinstance.py:1426} INFO - Exporting the following env vars:
AIRFLOW_CTX_DAG_OWNER=***
AIRFLOW_CTX_DAG_ID=weekly_batch
AIRFLOW_CTX_TASK_ID=download_dataset_task
AIRFLOW_CTX_EXECUTION_DATE=2022-10-11T05:09:22.800747+00:00
AIRFLOW_CTX_DAG_RUN_ID=manual__2022-10-11T05:09:22.800747+00:00
[2022-10-11 05:09:24,502] {subprocess.py:62} INFO - Tmp dir root location: 
 /tmp
[2022-10-11 05:09:24,504] {subprocess.py:74} INFO - Running command: ['bash', '-c', 'curl -sSL https://github.com/soldonmaybe/IYKRA/blob/main/bank-additional-full.csv > /home/***/gcs/data/bank-additional-full.csv']
[2022-10-11 05:09:24,522] {subprocess.py:85} INFO - Output:
[2022-10-11 05:09:24,529] {subprocess.py:89} INFO - bash: /home/***/gcs/data/bank-additional-full.csv: No such file or directory
[2022-10-11 05:09:24,529] {subprocess.py:93} INFO - Command exited with return code 1
[2022-10-11 05:09:24,546] {taskinstance.py:1700} ERROR - Task failed with exception
Traceback (most recent call last):
  File "/home/airflow/.local/lib/python3.7/site-packages/airflow/models/taskinstance.py", line 1329, in _run_raw_task
    self._execute_task_with_callbacks(context)
  File "/home/airflow/.local/lib/python3.7/site-packages/airflow/models/taskinstance.py", line 1455, in _execute_task_with_callbacks
    result = self._execute_task(context, self.task)
  File "/home/airflow/.local/lib/python3.7/site-packages/airflow/models/taskinstance.py", line 1511, in _execute_task
    result = execute_callable(context=context)
  File "/home/airflow/.local/lib/python3.7/site-packages/airflow/operators/bash.py", line 188, in execute
    f'Bash command failed. The command returned a non-zero exit code {result.exit_code}.'
airflow.exceptions.AirflowException: Bash command failed. The command returned a non-zero exit code 1.
[2022-10-11 05:09:24,556] {taskinstance.py:1277} INFO - Marking task as UP_FOR_RETRY. dag_id=weekly_batch, task_id=download_dataset_task, execution_date=20221011T050922, start_date=20221011T050924, end_date=20221011T050924
[2022-10-11 05:09:24,594] {standard_task_runner.py:92} ERROR - Failed to execute job 64 for task download_dataset_task
Traceback (most recent call last):
  File "/home/airflow/.local/lib/python3.7/site-packages/airflow/task/task_runner/standard_task_runner.py", line 85, in _start_by_fork
    args.func(args, dag=self.dag)
  File "/home/airflow/.local/lib/python3.7/site-packages/airflow/cli/cli_parser.py", line 48, in command
    return func(*args, **kwargs)
  File "/home/airflow/.local/lib/python3.7/site-packages/airflow/utils/cli.py", line 92, in wrapper
    return f(*args, **kwargs)
  File "/home/airflow/.local/lib/python3.7/site-packages/airflow/cli/commands/task_command.py", line 298, in task_run
    _run_task_by_selected_method(args, dag, ti)
  File "/home/airflow/.local/lib/python3.7/site-packages/airflow/cli/commands/task_command.py", line 107, in _run_task_by_selected_method
    _run_raw_task(args, ti)
  File "/home/airflow/.local/lib/python3.7/site-packages/airflow/cli/commands/task_command.py", line 184, in _run_raw_task
    error_file=args.error_file,
  File "/home/airflow/.local/lib/python3.7/site-packages/airflow/utils/session.py", line 70, in wrapper
    return func(*args, session=session, **kwargs)
  File "/home/airflow/.local/lib/python3.7/site-packages/airflow/models/taskinstance.py", line 1329, in _run_raw_task
    self._execute_task_with_callbacks(context)
  File "/home/airflow/.local/lib/python3.7/site-packages/airflow/models/taskinstance.py", line 1455, in _execute_task_with_callbacks
    result = self._execute_task(context, self.task)
  File "/home/airflow/.local/lib/python3.7/site-packages/airflow/models/taskinstance.py", line 1511, in _execute_task
    result = execute_callable(context=context)
  File "/home/airflow/.local/lib/python3.7/site-packages/airflow/operators/bash.py", line 188, in execute
    f'Bash command failed. The command returned a non-zero exit code {result.exit_code}.'
airflow.exceptions.AirflowException: Bash command failed. The command returned a non-zero exit code 1.
[2022-10-11 05:09:24,643] {local_task_job.py:154} INFO - Task exited with return code 1
[2022-10-11 05:09:24,686] {local_task_job.py:264} INFO - 0 downstream tasks scheduled from follow-on schedule check
